Workbook

Sheet 📊 Summary
A1: ✦ OF CHATTER — ANNUAL SUMMARY ✦
A2: Auto-pulls from each month tab • Week = Mon–Sun • Absences excluded from totals
A4: TO ADD A NEW MONTH: Copy any tab → rename → change Month/Year dropdowns → clear Gross Sales (blue cells) → log away!
A5: TO MARK ABSENT: On the month tab, click the Status cell (column L) for that day and select 'Absent' from the dropdown. Salary won't be counted.
A6: 3% — Net $0–$499 | D6: 4% — Net $500–$999 | G6: 5% — Net $1,000+
A8: 📅 2026
A9: # | B9: Month | C9: Shift | D9: Gross ($) | E9: Net ($) | F9: Base ($) | G9: Comm ($) | H9: Total ($) | I9: Total (₱) | J9: Absences
A10: 1 | B10: =IFERROR('Jan 2026'!C3&" '"&RIGHT('Jan 2026'!D3,2),"Jan 2026") -> January '26 | C10: =IFERROR('Jan 2026'!C4,"—") -> 4:00 PM – 12:00 MN | D10: =IFERROR('Jan 2026'!D48,0) -> 0 | E10: =IFERROR('Jan 2026'!E48,0) -> 0 | F10: =IFERROR('Jan 2026'!G48,0) -> 416 | G10: =IFERROR('Jan 2026'!I48,0) -> 0 | H10: =IFERROR('Jan 2026'!J48,0) -> 416 | I10: =IFERROR('Jan 2026'!K48,0) -> 24128 | J10: =IFERROR(LEFT('Jan 2026'!L48,FIND(" ",'Jan 2026'!L48)-1),"0") -> 0
A11: 2 | B11: =IFERROR('Feb 2026'!C3&" '"&RIGHT('Feb 2026'!D3,2),"Feb 2026") -> February '26 | C11: =IFERROR('Feb 2026'!C4,"—") -> 4:00 PM – 12:00 MN | D11: =IFERROR('Feb 2026'!D48,0) -> 0 | E11: =IFERROR('Feb 2026'!E48,0) -> 0 | F11: =IFERROR('Feb 2026'!G48,0) -> 384 | G11: =IFERROR('Feb 2026'!I48,0) -> 0 | H11: =IFERROR('Feb 2026'!J48,0) -> 384 | I11: =IFERROR('Feb 2026'!K48,0) -> 22272 | J11: =IFERROR(LEFT('Feb 2026'!L48,FIND(" ",'Feb 2026'!L48)-1),"0") -> 0
A12: 3 | B12: =IFERROR('Mar 2026'!C3&" '"&RIGHT('Mar 2026'!D3,2),"Mar 2026") -> March '26 | C12: =IFERROR('Mar 2026'!C4,"—") -> 4:00 PM – 12:00 MN | D12: =IFERROR('Mar 2026'!D56,0) -> 91 | E12: =IFERROR('Mar 2026'!E56,0) -> 72.8 | F12: =IFERROR('Mar 2026'!G56,0) -> 416 | G12: =IFERROR('Mar 2026'!I56,0) -> 2.184 | H12: =IFERROR('Mar 2026'!J56,0) -> 418.184 | I12: =IFERROR('Mar 2026'!K56,0) -> 24254.672 | J12: =IFERROR(LEFT('Mar 2026'!L56,FIND(" ",'Mar 2026'!L56)-1),"0") -> 1
A13: 4 | B13: =IFERROR('Apr 2026'!C3&" '"&RIGHT('Apr 2026'!D3,2),"Apr 2026") -> April '26 | C13: =IFERROR('Apr 2026'!C4,"—") -> 4:00 PM – 12:00 MN | D13: =IFERROR('Apr 2026'!D48,0) -> 0 | E13: =IFERROR('Apr 2026'!E48,0) -> 0 | F13: =IFERROR('Apr 2026'!G48,0) -> 400 | G13: =IFERROR('Apr 2026'!I48,0) -> 0 | H13: =IFERROR('Apr 2026'!J48,0) -> 400 | I13: =IFERROR('Apr 2026'!K48,0) -> 23200 | J13: =IFERROR(LEFT('Apr 2026'!L48,FIND(" ",'Apr 2026'!L48)-1),"0") -> 0
A14: 5 | B14: =IFERROR('May 2026'!C3&" '"&RIGHT('May 2026'!D3,2),"May 2026") -> May '26 | C14: =IFERROR('May 2026'!C4,"—") -> 4:00 PM – 12:00 MN | D14: =IFERROR('May 2026'!D48,0) -> 0 | E14: =IFERROR('May 2026'!E48,0) -> 0 | F14: =IFERROR('May 2026'!G48,0) -> 432 | G14: =IFERROR('May 2026'!I48,0) -> 0 | H14: =IFERROR('May 2026'!J48,0) -> 432 | I14: =IFERROR('May 2026'!K48,0) -> 25056 | J14: =IFERROR(LEFT('May 2026'!L48,FIND(" ",'May 2026'!L48)-1),"0") -> 0
A15: 6 | B15: =IFERROR('Jun 2026'!C3&" '"&RIGHT('Jun 2026'!D3,2),"Jun 2026") -> June '26 | C15: =IFERROR('Jun 2026'!C4,"—") -> 4:00 PM – 12:00 MN | D15: =IFERROR('Jun 2026'!D48,0) -> 0 | E15: =IFERROR('Jun 2026'!E48,0) -> 0 | F15: =IFERROR('Jun 2026'!G48,0) -> 416 | G15: =IFERROR('Jun 2026'!I48,0) -> 0 | H15: =IFERROR('Jun 2026'!J48,0) -> 416 | I15: =IFERROR('Jun 2026'!K48,0) -> 24128 | J15: =IFERROR(LEFT('Jun 2026'!L48,FIND(" ",'Jun 2026'!L48)-1),"0") -> 0
A16: 7 | B16: =IFERROR('Jul 2026'!C3&" '"&RIGHT('Jul 2026'!D3,2),"Jul 2026") -> July '26 | C16: =IFERROR('Jul 2026'!C4,"—") -> 4:00 PM – 12:00 MN | D16: =IFERROR('Jul 2026'!D48,0) -> 0 | E16: =IFERROR('Jul 2026'!E48,0) -> 0 | F16: =IFERROR('Jul 2026'!G48,0) -> 416 | G16: =IFERROR('Jul 2026'!I48,0) -> 0 | H16: =IFERROR('Jul 2026'!J48,0) -> 416 | I16: =IFERROR('Jul 2026'!K48,0) -> 24128 | J16: =IFERROR(LEFT('Jul 2026'!L48,FIND(" ",'Jul 2026'!L48)-1),"0") -> 0
A17: 8 | B17: =IFERROR('Aug 2026'!C3&" '"&RIGHT('Aug 2026'!D3,2),"Aug 2026") -> August '26 | C17: =IFERROR('Aug 2026'!C4,"—") -> 4:00 PM – 12:00 MN | D17: =IFERROR('Aug 2026'!D56,0) -> 0 | E17: =IFERROR('Aug 2026'!E56,0) -> 0 | F17: =IFERROR('Aug 2026'!G56,0) -> 432 | G17: =IFERROR('Aug 2026'!I56,0) -> 0 | H17: =IFERROR('Aug 2026'!J56,0) -> 432 | I17: =IFERROR('Aug 2026'!K56,0) -> 25056 | J17: =IFERROR(LEFT('Aug 2026'!L56,FIND(" ",'Aug 2026'!L56)-1),"0") -> 0
A18: 9 | B18: =IFERROR('Sep 2026'!C3&" '"&RIGHT('Sep 2026'!D3,2),"Sep 2026") -> September '26 | C18: =IFERROR('Sep 2026'!C4,"—") -> 4:00 PM – 12:00 MN | D18: =IFERROR('Sep 2026'!D48,0) -> 0 | E18: =IFERROR('Sep 2026'!E48,0) -> 0 | F18: =IFERROR('Sep 2026'!G48,0) -> 416 | G18: =IFERROR('Sep 2026'!I48,0) -> 0 | H18: =IFERROR('Sep 2026'!J48,0) -> 416 | I18: =IFERROR('Sep 2026'!K48,0) -> 24128 | J18: =IFERROR(LEFT('Sep 2026'!L48,FIND(" ",'Sep 2026'!L48)-1),"0") -> 0
A19: 10 | B19: =IFERROR('Oct 2026'!C3&" '"&RIGHT('Oct 2026'!D3,2),"Oct 2026") -> October '26 | C19: =IFERROR('Oct 2026'!C4,"—") -> 4:00 PM – 12:00 MN | D19: =IFERROR('Oct 2026'!D48,0) -> 0 | E19: =IFERROR('Oct 2026'!E48,0) -> 0 | F19: =IFERROR('Oct 2026'!G48,0) -> 416 | G19: =IFERROR('Oct 2026'!I48,0) -> 0 | H19: =IFERROR('Oct 2026'!J48,0) -> 416 | I19: =IFERROR('Oct 2026'!K48,0) -> 24128 | J19: =IFERROR(LEFT('Oct 2026'!L48,FIND(" ",'Oct 2026'!L48)-1),"0") -> 0
A20: 11 | B20: =IFERROR('Nov 2026'!C3&" '"&RIGHT('Nov 2026'!D3,2),"Nov 2026") -> November '26 | C20: =IFERROR('Nov 2026'!C4,"—") -> 4:00 PM – 12:00 MN | D20: =IFERROR('Nov 2026'!D56,0) -> 0 | E20: =IFERROR('Nov 2026'!E56,0) -> 0 | F20: =IFERROR('Nov 2026'!G56,0) -> 416 | G20: =IFERROR('Nov 2026'!I56,0) -> 0 | H20: =IFERROR('Nov 2026'!J56,0) -> 416 | I20: =IFERROR('Nov 2026'!K56,0) -> 24128 | J20: =IFERROR(LEFT('Nov 2026'!L56,FIND(" ",'Nov 2026'!L56)-1),"0") -> 0
A21: 12 | B21: =IFERROR('Dec 2026'!C3&" '"&RIGHT('Dec 2026'!D3,2),"Dec 2026") -> December '26 | C21: =IFERROR('Dec 2026'!C4,"—") -> 4:00 PM – 12:00 MN | D21: =IFERROR('Dec 2026'!D48,0) -> 0 | E21: =IFERROR('Dec 2026'!E48,0) -> 0 | F21: =IFERROR('Dec 2026'!G48,0) -> 416 | G21: =IFERROR('Dec 2026'!I48,0) -> 0 | H21: =IFERROR('Dec 2026'!J48,0) -> 416 | I21: =IFERROR('Dec 2026'!K48,0) -> 24128 | J21: =IFERROR(LEFT('Dec 2026'!L48,FIND(" ",'Dec 2026'!L48)-1),"0") -> 0
A22: 2026 TOTAL | D22: =SUM(D10:D21) -> 91 | E22: =SUM(E10:E21) -> 72.8 | F22: =SUM(F10:F21) -> 4976 | G22: =SUM(G10:G21) -> 2.184 | H22: =SUM(H10:H21) -> 4978.184 | I22: =SUM(I10:I21) -> 288734.67 | J22: =SUM(J10:J21) -> 0
A24: 📅 2027
A25: # | B25: Month | C25: Shift | D25: Gross ($) | E25: Net ($) | F25: Base ($) | G25: Comm ($) | H25: Total ($) | I25: Total (₱) | J25: Absences
A26: 1 | B26: =IFERROR('Jan 2027'!C3&" '"&RIGHT('Jan 2027'!D3,2),"Jan 2027") -> January '27 | C26: =IFERROR('Jan 2027'!C4,"—") -> 4:00 PM – 12:00 MN | D26: =IFERROR('Jan 2027'!D48,0) -> 0 | E26: =IFERROR('Jan 2027'!E48,0) -> 0 | F26: =IFERROR('Jan 2027'!G48,0) -> 432 | G26: =IFERROR('Jan 2027'!I48,0) -> 0 | H26: =IFERROR('Jan 2027'!J48,0) -> 432 | I26: =IFERROR('Jan 2027'!K48,0) -> 25056 | J26: =IFERROR(LEFT('Jan 2027'!L48,FIND(" ",'Jan 2027'!L48)-1),"0") -> 0
A27: 2 | B27: =IFERROR('Feb 2027'!C3&" '"&RIGHT('Feb 2027'!D3,2),"Feb 2027") -> February '27 | C27: =IFERROR('Feb 2027'!C4,"—") -> 4:00 PM – 12:00 MN | D27: =IFERROR('Feb 2027'!D40,0) -> 0 | E27: =IFERROR('Feb 2027'!E40,0) -> 0 | F27: =IFERROR('Feb 2027'!G40,0) -> 384 | G27: =IFERROR('Feb 2027'!I40,0) -> 0 | H27: =IFERROR('Feb 2027'!J40,0) -> 384 | I27: =IFERROR('Feb 2027'!K40,0) -> 22272 | J27: =IFERROR(LEFT('Feb 2027'!L40,FIND(" ",'Feb 2027'!L40)-1),"0") -> 0
A28: 3 | B28: =IFERROR('Mar 2027'!C3&" '"&RIGHT('Mar 2027'!D3,2),"Mar 2027") -> March '27 | C28: =IFERROR('Mar 2027'!C4,"—") -> 4:00 PM – 12:00 MN | D28: =IFERROR('Mar 2027'!D48,0) -> 0 | E28: =IFERROR('Mar 2027'!E48,0) -> 0 | F28: =IFERROR('Mar 2027'!G48,0) -> 432 | G28: =IFERROR('Mar 2027'!I48,0) -> 0 | H28: =IFERROR('Mar 2027'!J48,0) -> 432 | I28: =IFERROR('Mar 2027'!K48,0) -> 25056 | J28: =IFERROR(LEFT('Mar 2027'!L48,FIND(" ",'Mar 2027'!L48)-1),"0") -> 0
A29: 4 | B29: =IFERROR('Apr 2027'!C3&" '"&RIGHT('Apr 2027'!D3,2),"Apr 2027") -> April '27 | C29: =IFERROR('Apr 2027'!C4,"—") -> 4:00 PM – 12:00 MN | D29: =IFERROR('Apr 2027'!D48,0) -> 0 | E29: =IFERROR('Apr 2027'!E48,0) -> 0 | F29: =IFERROR('Apr 2027'!G48,0) -> 400 | G29: =IFERROR('Apr 2027'!I48,0) -> 0 | H29: =IFERROR('Apr 2027'!J48,0) -> 400 | I29: =IFERROR('Apr 2027'!K48,0) -> 23200 | J29: =IFERROR(LEFT('Apr 2027'!L48,FIND(" ",'Apr 2027'!L48)-1),"0") -> 0
A30: 5 | B30: =IFERROR('May 2027'!C3&" '"&RIGHT('May 2027'!D3,2),"May 2027") -> May '27 | C30: =IFERROR('May 2027'!C4,"—") -> 4:00 PM – 12:00 MN | D30: =IFERROR('May 2027'!D56,0) -> 0 | E30: =IFERROR('May 2027'!E56,0) -> 0 | F30: =IFERROR('May 2027'!G56,0) -> 432 | G30: =IFERROR('May 2027'!I56,0) -> 0 | H30: =IFERROR('May 2027'!J56,0) -> 432 | I30: =IFERROR('May 2027'!K56,0) -> 25056 | J30: =IFERROR(LEFT('May 2027'!L56,FIND(" ",'May 2027'!L56)-1),"0") -> 0
A31: 6 | B31: =IFERROR('Jun 2027'!C3&" '"&RIGHT('Jun 2027'!D3,2),"Jun 2027") -> June '27 | C31: =IFERROR('Jun 2027'!C4,"—") -> 4:00 PM – 12:00 MN | D31: =IFERROR('Jun 2027'!D48,0) -> 0 | E31: =IFERROR('Jun 2027'!E48,0) -> 0 | F31: =IFERROR('Jun 2027'!G48,0) -> 416 | G31: =IFERROR('Jun 2027'!I48,0) -> 0 | H31: =IFERROR('Jun 2027'!J48,0) -> 416 | I31: =IFERROR('Jun 2027'!K48,0) -> 24128 | J31: =IFERROR(LEFT('Jun 2027'!L48,FIND(" ",'Jun 2027'!L48)-1),"0") -> 0
A32: 7 | B32: =IFERROR('Jul 2027'!C3&" '"&RIGHT('Jul 2027'!D3,2),"Jul 2027") -> July '27 | C32: =IFERROR('Jul 2027'!C4,"—") -> 4:00 PM – 12:00 MN | D32: =IFERROR('Jul 2027'!D48,0) -> 0 | E32: =IFERROR('Jul 2027'!E48,0) -> 0 | F32: =IFERROR('Jul 2027'!G48,0) -> 416 | G32: =IFERROR('Jul 2027'!I48,0) -> 0 | H32: =IFERROR('Jul 2027'!J48,0) -> 416 | I32: =IFERROR('Jul 2027'!K48,0) -> 24128 | J32: =IFERROR(LEFT('Jul 2027'!L48,FIND(" ",'Jul 2027'!L48)-1),"0") -> 0
A33: 8 | B33: =IFERROR('Aug 2027'!C3&" '"&RIGHT('Aug 2027'!D3,2),"Aug 2027") -> August '27 | C33: =IFERROR('Aug 2027'!C4,"—") -> 4:00 PM – 12:00 MN | D33: =IFERROR('Aug 2027'!D56,0) -> 0 | E33: =IFERROR('Aug 2027'!E56,0) -> 0 | F33: =IFERROR('Aug 2027'!G56,0) -> 432 | G33: =IFERROR('Aug 2027'!I56,0) -> 0 | H33: =IFERROR('Aug 2027'!J56,0) -> 432 | I33: =IFERROR('Aug 2027'!K56,0) -> 25056 | J33: =IFERROR(LEFT('Aug 2027'!L56,FIND(" ",'Aug 2027'!L56)-1),"0") -> 0
A34: 9 | B34: =IFERROR('Sep 2027'!C3&" '"&RIGHT('Sep 2027'!D3,2),"Sep 2027") -> September '27 | C34: =IFERROR('Sep 2027'!C4,"—") -> 4:00 PM – 12:00 MN | D34: =IFERROR('Sep 2027'!D48,0) -> 0 | E34: =IFERROR('Sep 2027'!E48,0) -> 0 | F34: =IFERROR('Sep 2027'!G48,0) -> 400 | G34: =IFERROR('Sep 2027'!I48,0) -> 0 | H34: =IFERROR('Sep 2027'!J48,0) -> 400 | I34: =IFERROR('Sep 2027'!K48,0) -> 23200 | J34: =IFERROR(LEFT('Sep 2027'!L48,FIND(" ",'Sep 2027'!L48)-1),"0") -> 0
A35: 10 | B35: =IFERROR('Oct 2027'!C3&" '"&RIGHT('Oct 2027'!D3,2),"Oct 2027") -> October '27 | C35: =IFERROR('Oct 2027'!C4,"—") -> 4:00 PM – 12:00 MN | D35: =IFERROR('Oct 2027'!D48,0) -> 0 | E35: =IFERROR('Oct 2027'!E48,0) -> 0 | F35: =IFERROR('Oct 2027'!G48,0) -> 432 | G35: =IFERROR('Oct 2027'!I48,0) -> 0 | H35: =IFERROR('Oct 2027'!J48,0) -> 432 | I35: =IFERROR('Oct 2027'!K48,0) -> 25056 | J35: =IFERROR(LEFT('Oct 2027'!L48,FIND(" ",'Oct 2027'!L48)-1),"0") -> 0
A36: 11 | B36: =IFERROR('Nov 2027'!C3&" '"&RIGHT('Nov 2027'!D3,2),"Nov 2027") -> November '27 | C36: =IFERROR('Nov 2027'!C4,"—") -> 4:00 PM – 12:00 MN | D36: =IFERROR('Nov 2027'!D48,0) -> 0 | E36: =IFERROR('Nov 2027'!E48,0) -> 0 | F36: =IFERROR('Nov 2027'!G48,0) -> 416 | G36: =IFERROR('Nov 2027'!I48,0) -> 0 | H36: =IFERROR('Nov 2027'!J48,0) -> 416 | I36: =IFERROR('Nov 2027'!K48,0) -> 24128 | J36: =IFERROR(LEFT('Nov 2027'!L48,FIND(" ",'Nov 2027'!L48)-1),"0") -> 0
A37: 12 | B37: =IFERROR('Dec 2027'!C3&" '"&RIGHT('Dec 2027'!D3,2),"Dec 2027") -> December '27 | C37: =IFERROR('Dec 2027'!C4,"—") -> 4:00 PM – 12:00 MN | D37: =IFERROR('Dec 2027'!D48,0) -> 0 | E37: =IFERROR('Dec 2027'!E48,0) -> 0 | F37: =IFERROR('Dec 2027'!G48,0) -> 416 | G37: =IFERROR('Dec 2027'!I48,0) -> 0 | H37: =IFERROR('Dec 2027'!J48,0) -> 416 | I37: =IFERROR('Dec 2027'!K48,0) -> 24128 | J37: =IFERROR(LEFT('Dec 2027'!L48,FIND(" ",'Dec 2027'!L48)-1),"0") -> 0
A38: 2027 TOTAL | D38: =SUM(D26:D37) -> 0 | E38: =SUM(E26:E37) -> 0 | F38: =SUM(F26:F37) -> 5008 | G38: =SUM(G26:G37) -> 0 | H38: =SUM(H26:H37) -> 5008 | I38: =SUM(I26:I37) -> 290464 | J38: =SUM(J26:J37) -> 0

Sheet Jan 2026
A1: ✦ OF CHATTER SALARY TRACKER ✦
A2: =C4&" • Week: Mon–Sun • Thursday = Rest Day • $2/hr × 8hrs = $16/day • Blue = your input" -> 4:00 PM – 12:00 MN • Week: Mon–Sun • Thursday = Rest Day • $2/hr × 8hrs = $16/day • Blue = your input
A3: 📅 MONTH & YEAR: | C3: January | D3: 2026 | E3: ← Change to update all dates | H3: Daily Goal ($): | J3: 50 | K3: PHP Rate: | L3: 58 | M3: ← editable
A4: 🕐 SHIFT SCHEDULE: | C4: 4:00 PM – 12:00 MN | F4: ← Pick your shift • Pay stays $2/hr regardless of shift
A5: MONTH-TO-DATE | D5: =SUMIFS(D8:D42,D8:D42,"<>0",C8:C42,"<>Thursday",C8:C42,"<>",L8:L42,"<>Absent") -> 0 | E5: =SUMIFS(E8:E42,E8:E42,"<>0",C8:C42,"<>Thursday",C8:C42,"<>",L8:L42,"<>Absent") -> 0 | G5: =SUMIFS(G8:G42,G8:G42,"<>0",C8:C42,"<>Thursday",C8:C42,"<>",L8:L42,"<>Absent") -> 416 | I5: =SUMIFS(I8:I42,I8:I42,"<>0",C8:C42,"<>Thursday",C8:C42,"<>",L8:L42,"<>Absent") -> 0 | J5: =SUMIFS(J8:J42,J8:J42,"<>0",C8:C42,"<>Thursday",C8:C42,"<>",L8:L42,"<>Absent") -> 416 | K5: =SUMIFS(K8:K42,K8:K42,"<>0",C8:C42,"<>Thursday",C8:C42,"<>",L8:L42,"<>Absent") -> 24128 | L5: =COUNTIF(L8:L42,"✓")&" / "&COUNTIFS(C8:C42,"<>Thursday",C8:C42,"<>",L8:L42,"<>Absent")&" days goal hit" -> 0 / 30 days goal hit
A6: BEST THIS MONTH | D6: =IF(MAX(D8:D42)=0,"—",MAX(D8:D42)) -> — | E6: =IF(MAX(E8:E42)=0,"—",MAX(E8:E42)) -> — | F6: PROJECTED MONTH: | H6: =IFERROR(J5/MAX(1,COUNTIFS(C8:C42,"<>Thursday",J8:J42,"<>0",L8:L42,"<>Absent")),0) -> 16 | I6: =IFERROR(J5/MAX(1,COUNTIFS(C8:C42,"<>Thursday",J8:J42,"<>0",L8:L42,"<>Absent"))*COUNTIFS(C8:C42,"<>Thursday",B8:B42,"<>",L8:L42,"<>Absent"),0) -> 480 | J6: =IFERROR(I6*L3,0) -> 27840 | L6: ← projected (excludes absences)
A7: # | B7: Date | C7: Day | D7: Gross Sales ($) | E7: Net Sales (Gross×80%) | F7: Hours Worked | G7: Base Pay ($) | H7: Comm Rate | I7: Commission ($) | J7: TOTAL SALARY ($) | K7: Total (PHP ₱) | L7: Status | M7: Notes
A8: =IF(NOT(MONTH(DATE(VALUE(D3),IF(C3="January",1,IF(C3="February",2,IF(C3="March",3,IF(C3="April",4,IF(C3="May",5,IF(C3="June",6,IF(C3="July",7,IF(C3="August",8,IF(C3="September",9,IF(C3="October",10,IF(C3="November",11,12))))))))))),1)-WEEKDAY(DATE(VALUE(D3),IF(C3="January",1,IF(C3="February",2,IF(C3="March",3,IF(C3="April",4,IF(C3="May",5,IF(C3="June",6,IF(C3="July",7,IF(C3="August",8,IF(C3="September",9,IF(C3="October",10,IF(C3="November",11,12))))))))))),1),3)+0)=IF(C3="January",1,IF(C3="February",2,IF(C3="March",3,IF(C3="April",4,IF(C3="May",5,IF(C3="June",6,IF(C3="July",7,IF(C3="August",8,IF(C3="September",9,IF(C3="October",10,IF(C3="November",11,12)))))))))))),"",IF(TEXT(DATE(VALUE(D3),IF(C3="January",1,IF(C3="February",2,IF(C3="March",3,IF(C3="April",4,IF(C3="May",5,IF(C3="June",6,IF(C3="July",7,IF(C3="August",8,IF(C3="September",9,IF(C3="October",10,IF(C3="November",11,12))))))))))),1)-WEEKDAY(DATE(VALUE(D3),IF(C3="January",1,IF(C3="February",2,IF(C3="March",3,IF(C3="April",4,IF(C3="May",5,IF(C3="June",6,IF(C3="July",7,IF(C3="August",8,IF(C3="September",9,IF(C3="October",10,IF(C3="November",11,12))))))))))),1),3)+0,"DDDD")="Thursday","—",DAY(DATE(VALUE(D3),IF(C3="January",1,IF(C3="February",2,IF(C3="March",3,IF(C3="April",4,IF(C3="May",5,IF(C3="June",6,IF(C3="July",7,IF(C3="August",8,IF(C3="September",9,IF(C3="October",10,IF(C3="November",11,12))))))))))),1)-WEEKDAY(DATE(VALUE(D3),IF(C3="January",1,IF(C3="February",2,IF(C3="March",3,IF(C3="April",4,IF(C3="May",5,IF(C3="June",6,IF(C3="July",7,IF(C3="August",8,IF(C3="September",9,IF(C3="October",10,IF(C3="November",11,12))))))))))),1),3)+0))) | B8: =IF(NOT(MONTH(DATE(VALUE(D3),IF(C3="January",1,IF(C3="February",2,IF(C3="March",3,IF(C3="April",4,IF(C3="May",5,IF(C3="June",6,IF(C3="July",7,IF(C3="August",8,IF(C3="September",9,IF(C3="October",10,IF(C3="November",11,12))))))))))),1)-WEEKDAY(DATE(VALUE(D3),IF(C3="January",1,IF(C3="February",2,IF(C3="March",3,IF(C3="April",4,IF(C3="May",5,IF(C3="June",6,IF(C3="July",7,IF(C3="August",8,IF(C3="September",9,IF(C3="October",10,IF(C3="November",11,12))))))))))),1),3)+0)=IF(C3="January",1,IF(C3="February",2,IF(C3="March",3,IF(C3="April",4,IF(C3="May",5,IF(C3="June",6,IF(C3="July",7,IF(C3="August",8,IF(C3="September",9,IF(C3="October",10,IF(C3="November",11,12)))))))))))),"",DATE(VALUE(D3),IF(C3="January",1,IF(C3="February",2,IF(C3="March",3,IF(C3="April",4,IF(C3="May",5,IF(C3="June",6,IF(C3="July",7,IF(C3="August",8,IF(C3="September",9,IF(C3="October",10,IF(C3="November",11,12))))))))))),1)-WEEKDAY(DATE(VALUE(D3),IF(C3="January",1,IF(C3="February",2,IF(C3="March",3,IF(C3="April",4,IF(C3="May",5,IF(C3="June",6,IF(C3="July",7,IF(C3="August",8,IF(C3="September",9,IF(C3="October",10,IF(C3="November",11,12))))))))))),1),3)+0) | C8: =IF(NOT(MONTH(DATE(VALUE(D3),IF(C3="January",1,IF(C3="February",2,IF(C3="March",3,IF(C3="April",4,IF(C3="May",5,IF(C3="June",6,IF(C3="July",7,IF(C3="August",8,IF(C3="September",9,IF(C3="October",10,IF(C3="November",11,12))))))))))),1)-WEEKDAY(DATE(VALUE(D3),IF(C3="January",1,IF(C3="February",2,IF(C3="March",3,IF(C3="April",4,IF(C3="May",5,IF(C3="June",6,IF(C3="July",7,IF(C3="August",8,IF(C3="September",9,IF(C3="October",10,IF(C3="November",11,12))))))))))),1),3)+0)=IF(C3="January",1,IF(C3="February",2,IF(C3="March",3,IF(C3="April",4,IF(C3="May",5,IF(C3="June",6,IF(C3="July",7,IF(C3="August",8,IF(C3="September",9,IF(C3="October",10,IF(C3="November",11,12)))))))))))),"",TEXT(B8,"DDDD")) | D8: 0 | E8: =IF(AND(MONTH(DATE(VALUE(D3),IF(C3="January",1,IF(C3="February",2,IF(C3="March",3,IF(C3="April",4,IF(C3="May",5,IF(C3="June",6,IF(C3="July",7,IF(C3="August",8,IF(C3="September",9,IF(C3="October",10,IF(C3="November",11,12))))))))))),1)-WEEKDAY(DATE(VALUE(D3),IF(C3="January",1,IF(C3="February",2,IF(C3="March",3,IF(C3="April",4,IF(C3="May",5,IF(C3="June",6,IF(C3="July",7,IF(C3="August",8,IF(C3="September",9,IF(C3="October",10,IF(C3="November",11,12))))))))))),1),3)+0)=IF(C3="January",1,IF(C3="February",2,IF(C3="March",3,IF(C3="April",4,IF(C3="May",5,IF(C3="June",6,IF(C3="July",7,IF(C3="August",8,IF(C3="September",9,IF(C3="October",10,IF(C3="November",11,12))))))))))),NOT(TEXT(DATE(VALUE(D3),IF(C3="January",1,IF(C3="February",2,IF(C3="March",3,IF(C3="April",4,IF(C3="May",5,IF(C3="June",6,IF(C3="July",7,IF(C3="August",8,IF(C3="September",9,IF(C3="October",10,IF(C3="November",11,12))))))))))),1)-WEEKDAY(DATE(VALUE(D3),IF(C3="January",1,IF(C3="February",2,IF(C3="March",3,IF(C3="April",4,IF(C3="May",5,IF(C3="June",6,IF(C3="July",7,IF(C3="August",8,IF(C3="September",9,IF(C3="October",10,IF(C3="November",11,12))))))))))),1),3)+0,"DDDD")="Thursday"),NOT(L8="Absent")),IF(D8=0,0,D8*0.8),0) -> 0 | F8: =IF(AND(MONTH(DATE(VALUE(D3),IF(C3="January",1,IF(C3="February",2,IF(C3="March",3,IF(C3="April",4,IF(C3="May",5,IF(C3="June",6,IF(C3="July",7,IF(C3="August",8,IF(C3="September",9,IF(C3="October",10,IF(C3="November",11,12))))))))))),1)-WEEKDAY(DATE(VALUE(D3),IF(C3="January",1,IF(C3="February",2,IF(C3="March",3,IF(C3="April",4,IF(C3="May",5,IF(C3="June",6,IF(C3="July",7,IF(C3="August",8,IF(C3="September",9,IF(C3="October",10,IF(C3="November",11,12))))))))))),1),3)+0)=IF(C3="January",1,IF(C3="February",2,IF(C3="March",3,IF(C3="April",4,IF(C3="May",5,IF(C3="June",6,IF(C3="July",7,IF(C3="August",8,IF(C3="September",9,IF(C3="October",10,IF(C3="November",11,12))))))))))),NOT(TEXT(DATE(VALUE(D3),IF(C3="January",1,IF(C3="February",2,IF(C3="March",3,IF(C3="April",4,IF(C3="May",5,IF(C3="June",6,IF(C3="July",7,IF(C3="August",8,IF(C3="September",9,IF(C3="October",10,IF(C3="November",11,12))))))))))),1)-WEEKDAY(DATE(VALUE(D3),IF(C3="January",1,IF(C3="February",2,IF(C3="March",3,IF(C3="April",4,IF(C3="May",5,IF(C3="June",6,IF(C3="July",7,IF(C3="August",8,IF(C3="September",9,IF(C3="October",10,IF(C3="November",11,12))))))))))),1),3)+0,"DDDD")="Thursday"),NOT(L8="Absent")),8,0) -> 0 | G8: =IF(AND(MONTH(DATE(VALUE(D3),IF(C3="January",1,IF(C3="February",2,IF(C3="March",3,IF(C3="April",4,IF(C3="May",5,IF(C3="June",6,IF(C3="July",7,IF(C3="August",8,IF(C3="September",9,IF(C3="October",10,IF(C3="November",11,12))))))))))),1)-WEEKDAY(DATE(VALUE(D3),IF(C3="January",1,IF(C3="February",2,IF(C3="March",3,IF(C3="April",4,IF(C3="May",5,IF(C3="June",6,IF(C3="July",7,IF(C3="August",8,IF(C3="September",9,IF(C3="October",10,IF(C3="November",11,12))))))))))),1),3)+0)=IF(C3="January",1,IF(C3="February",2,IF(C3="March",3,IF(C3="April",4,IF(C3="May",5,IF(C3="June",6,IF(C3="July",7,IF(C3="August",8,IF(C3="September",9,IF(C3="October",10,IF(C3="November",11,12))))))))))),NOT(TEXT(DATE(VALUE(D3),IF(C3="January",1,IF(C3="February",2,IF(C3="March",3,IF(C3="April",4,IF(C3="May",5,IF(C3="June",6,IF(C3="July",7,IF(C3="August",8,IF(C3="September",9,IF(C3="October",10,IF(C3="November",11,12))))))))))),1)-WEEKDAY(DATE(VALUE(D3),IF(C3="January",1,IF(C3="February",2,IF(C3="March",3,IF(C3="April",4,IF(C3="May",5,IF(C3="June",6,IF(C3="July",7,IF(C3="August",8,IF(C3="September",9,IF(C3="October",10,IF(C3="November",11,12))))))))))),1),3)+0,"DDDD")="Thursday"),NOT(L8="Absent")),F8*2,0) -> 0 | H8: =IF(NOT(MONTH(DATE(VALUE(D3),IF(C3="January",1,IF(C3="February",2,IF(C3="March",3,IF(C3="April",4,IF(C3="May",5,IF(C3="June",6,IF(C3="July",7,IF(C3="August",8,IF(C3="September",9,IF(C3="October",10,IF(C3="November",11,12))))))))))),1)-WEEKDAY(DATE(VALUE(D3),IF(C3="January",1,IF(C3="February",2,IF(C3="March",3,IF(C3="April",4,IF(C3="May",5,IF(C3="June",6,IF(C3="July",7,IF(C3="August",8,IF(C3="September",9,IF(C3="October",10,IF(C3="November",11,12))))))))))),1),3)+0)=IF(C3="January",1,IF(C3="February",2,IF(C3="March",3,IF(C3="April",4,IF(C3="May",5,IF(C3="June",6,IF(C3="July",7,IF(C3="August",8,IF(C3="September",9,IF(C3="October",10,IF(C3="November",11,12)))))))))))),"",IF(TEXT(DATE(VALUE(D3),IF(C3="January",1,IF(C3="February",2,IF(C3="March",3,IF(C3="April",4,IF(C3="May",5,IF(C3="June",6,IF(C3="July",7,IF(C3="August",8,IF(C3="September",9,IF(C3="October",10,IF(C3="November",11,12))))))))))),1)-WEEKDAY(DATE(VALUE(D3),IF(C3="January",1,IF(C3="February",2,IF(C3="March",3,IF(C3="April",4,IF(C3="May",5,IF(C3="June",6,IF(C3="July",7,IF(C3="August",8,IF(C3="September",9,IF(C3="October",10,IF(C3="November",11,12))))))))))),1),3)+0,"DDDD")="Thursday","—",IF(L8="Absent","Absent",IF(E8=0,"0%",IF(E8<500,"3%",IF(E8<1000,"4%","5%")))))) | I8: =IF(AND(MONTH(DATE(VALUE(D3),IF(C3="January",1,IF(C3="February",2,IF(C3="March",3,IF(C3="April",4,IF(C3="May",5,IF(C3="June",6,IF(C3="July",7,IF(C3="August",8,IF(C3="September",9,IF(C3="October",10,IF(C3="November",11,12))))))))))),1)-WEEKDAY(DATE(VALUE(D3),IF(C3="January",1,IF(C3="February",2,IF(C3="March",3,IF(C3="April",4,IF(C3="May",5,IF(C3="June",6,IF(C3="July",7,IF(C3="August",8,IF(C3="September",9,IF(C3="October",10,IF(C3="November",11,12))))))))))),1),3)+0)=IF(C3="January",1,IF(C3="February",2,IF(C3="March",3,IF(C3="April",4,IF(C3="May",5,IF(C3="June",6,IF(C3="July",7,IF(C3="August",8,IF(C3="September",9,IF(C3="October",10,IF(C3="November",11,12))))))))))),NOT(TEXT(DATE(VALUE(D3),IF(C3="January",1,IF(C3="February",2,IF(C3="March",3,IF(C3="April",4,IF(C3="May",5,IF(C3="June",6,IF(C3="July",7,IF(C3="August",8,IF(C3="September",9,IF(C3="October",10,IF(C3="November",11,12))))))))))),1)-WEEKDAY(DATE(VALUE(D3),IF(C3="January",1,IF(C3="February",2,IF(C3="March",3,IF(C3="April",4,IF(C3="May",5,IF(C3="June",6,IF(C3="July",7,IF(C3="August",8,IF(C3="September",9,IF(C3="October",10,IF(C3="November",11,12))))))))))),1),3)+0,"DDDD")="Thursday"),NOT(L8="Absent")),IF(E8=0,0,IF(E8<500,E8*0.03,IF(E8<1000,E8*0.04,E8*0.05))),0) -> 0 | J8: =IF(AND(MONTH(DATE(VALUE(D3),IF(C3="January",1,IF(C3="February",2,IF(C3="March",3,IF(C3="April",4,IF(C3="May",5,IF(C3="June",6,IF(C3="July",7,IF(C3="August",8,IF(C3="September",9,IF(C3="October",10,IF(C3="November",11,12))))))))))),1)-WEEKDAY(DATE(VALUE(D3),IF(C3="January",1,IF(C3="February",2,IF(C3="March",3,IF(C3="April",4,IF(C3="May",5,IF(C3="June",6,IF(C3="July",7,IF(C3="August",8,IF(C3="September",9,IF(C3="October",10,IF(C3="November",11,12))))))))))),1),3)+0)=IF(C3="January",1,IF(C3="February",2,IF(C3="March",3,IF(C3="April",4,IF(C3="May",5,IF(C3="June",6,IF(C3="July",7,IF(C3="August",8,IF(C3="September",9,IF(C3="October",10,IF(C3="November",11,12))))))))))),NOT(TEXT(DATE(VALUE(D3),IF(C3="January",1,IF(C3="February",2,IF(C3="March",3,IF(C3="April",4,IF(C3="May",5,IF(C3="June",6,IF(C3="July",7,IF(C3="August",8,IF(C3="September",9,IF(C3="October",10,IF(C3="November",11,12))))))))))),1)-WEEKDAY(DATE(VALUE(D3),IF(C3="January",1,IF(C3="February",2,IF(C3="March",3,IF(C3="April",4,IF(C3="May",5,IF(C3="June",6,IF(C3="July",7,IF(C3="August",8,IF(C3="September",9,IF(C3="October",10,IF(C3="November",11,12))))))))))),1),3)+0,"DDDD")="Thursday"),NOT(L8="Absent")),G8+I8,0) -> 0 | K8: =IF(AND(MONTH(DATE(VALUE(D3),IF(C3="January",1,IF(C3="February",2,IF(C3="March",3,IF(C3="April",4,IF(C3="May",5,IF(C3="June",6,IF(C3="July",7,IF(C3="August",8,IF(C3="September",9,IF(C3="October",10,IF(C3="November",11,12))))))))))),1)-WEEKDAY(DATE(VALUE(D3),IF(C3="January",1,IF(C3="February",2,IF(C3="March",3,IF(C3="April",4,IF(C3="May",5,IF(C3="June",6,IF(C3="July",7,IF(C3="August",8,IF(C3="September",9,IF(C3="October",10,IF(C3="November",11,12))))))))))),1),3)+0)=IF(C3="January",1,IF(C3="February",2,IF(C3="March",3,IF(C3="April",4,IF(C3="May",5,IF(C3="June",6,IF(C3="July",7,IF(C3="August",8,IF(C3="September",9,IF(C3="October",10,IF(C3="November",11,12))))))))))),NOT(TEXT(DATE(VALUE(D3),IF(C3="January",1,IF(C3="February",2,IF(C3="March",3,IF(C3="April",4,IF(C3="May",5,IF(C3="June",6,IF(C3="July",7,IF(C3="August",8,IF(C3="September",9,IF(C3="October",10,IF(C3="November",11,12))))))))))),1)-WEEKDAY(DATE(VALUE(D3),IF(C3="January",1,IF(C3="February",2,IF(C3="March",3,IF(C3="April",4,IF(C3="May",5,IF(C3="June",6,IF(C3="July",7,IF(C3="August",8,IF(C3="September",9,IF(C3="October",10,IF(C3="November",11,12))))))))))),1),3)+0,"DDDD")="Thursday"),NOT(L8="Absent")),J8*$L$3,0) -> 0
A9: =IF(NOT(MONTH(DATE(VALUE(D3),IF(C3="January",1,IF(C3="February",2,IF(C3="March",3,IF(C3="April",4,IF(C3="May",5,IF(C3="June",6,IF(C3="July",7,IF(C3="August",8,IF(C3="September",9,IF(C3="October",10,IF(C3="November",11,12))))))))))),1)-WEEKDAY(DATE(VALUE(D3),IF(C3="January",1,IF(C3="February",2,IF(C3="March",3,IF(C3="April",4,IF(C3="May",5,IF(C3="June",6,IF(C3="July",7,IF(C3="August",8,IF(C3="September",9,IF(C3="October",10,IF(C3="November",11,12))))))))))),1),3)+1)=IF(C3="January",1,IF(C3="February",2,IF(C3="March",3,IF(C3="April",4,IF(C3="May",5,IF(C3="June",6,IF(C3="July",7,IF(C3="August",8,IF(C3="September",9,IF(C3="October",10,IF(C3="November",11,12)))))))))))),"",IF(TEXT(DATE(VALUE(D3),IF(C3="January",1,IF(C3="February",2,IF(C3="March",3,IF(C3="April",4,IF(C3="May",5,IF(C3="June",6,IF(C3="July",7,IF(C3="August",8,IF(C3="September",9,IF(C3="October",10,IF(C3="November",11,12))))))))))),1)-WEEKDAY(DATE(VALUE(D3),IF(C3="January",1,IF(C3="February",2,IF(C3="March",3,IF(C3="April",4,IF(C3="May",5,IF(C3="June",6,IF(C3="July",7,IF(C3="August",8,IF(C3="September",9,IF(C3="October",10,IF(C3="November",11,12))))))))))),1),3)+1,"DDDD")="Thursday","—",DAY(DATE(VALUE(D3),IF(C3="January",1,IF(C3="February",2,IF(C3="March",3,IF(C3="April",4,IF(C3="May",5,IF(C3="June",6,IF(C3="July",7,IF(C3="August",8,IF(C3="September",9,IF(C3="October",10,IF(C3="November",11,12))))))))))),1)-WEEKDAY(DATE(VALUE(D3),IF(C3="January",1,IF(C3="February",2,IF(C3="March",3,IF(C3="April",4,IF(C3="May",5,IF(C3="June",6,IF(C3="July",7,IF(C3="August",8,IF(C3="September",9,IF(C3="October",10,IF(C3="November",11,12))))))))))),1),3)+1))) | B9: =IF(NOT(MONTH(DATE(VALUE(D3),IF(C3="January",1,IF(C3="February",2,IF(C3="March",3,IF(C3="April",4,IF(C3="May",5,IF(C3="June",6,IF(C3="July",7,IF(C3="August",8,IF(C3="September",9,IF(C3="October",10,IF(C3="November",11,12))))))))))),1)-WEEKDAY(DATE(VALUE(D3),IF(C3="January",1,IF(C3="February",2,IF(C3="March",3,IF(C3="April",4,IF(C3="May",5,IF(C3="June",6,IF(C3="July",7,IF(C3="August",8,IF(C3="September",9,IF(C3="October",10,IF(C3="November",11,12))))))))))),1),3)+1)=IF(C3="January",1,IF(C3="February",2,IF(C3="March",3,IF(C3="April",4,IF(C3="May",5,IF(C3="June",6,IF(C3="July",7,IF(C3="August",8,IF(C3="September",9,IF(C3="October",10,IF(C3="November",11,12)))))))))))),"",DATE(VALUE(D3),IF(C3="January",1,IF(C3="February",2,IF(C3="March",3,IF(C3="April",4,IF(C3="May",5,IF(C3="June",6,IF(C3="July",7,IF(C3="August",8,IF(C3="September",9,IF(C3="October",10,IF(C3="November",11,12))))))))))),1)-WEEKDAY(DATE(VALUE(D3),IF(C3="January",1,IF(C3="February",2,IF(C3="March",3,IF(C3="April",4,IF(C3="May",5,IF(C3="June",6,IF(C3="July",7,IF(C3="August",8,IF(C3="September",9,IF(C3="October",10,IF(C3="November",11,12))))))))))),1),3)+1) | C9: =IF(NOT(MONTH(DATE(VALUE(D3),IF(C3="January",1,IF(C3="February",2,IF(C3="March",3,IF(C3="April",4,IF(C3="May",5,IF(C3="June",6,IF(C3="July",7,IF(C3="August",8,IF(C3="September",9,IF(C3="October",10,IF(C3="November",11,12))))))))))),1)-WEEKDAY(DATE(VALUE(D3),IF(C3="January",1,IF(C3="February",2,IF(C3="March",3,IF(C3="April",4,IF(C3="May",5,IF(C3="June",6,IF(C3="July",7,IF(C3="August",8,IF(C3="September",9,IF(C3="October",10,IF(C3="November",11,12))))))))))),1),3)+1)=IF(C3="January",1,IF(C3="February",2,IF(C3="March",3,IF(C3="April",4,IF(C3="May",5,IF(C3="June",6,IF(C3="July",7,IF(C3="August",8,IF(C3="September",9,IF(C3="October",10,IF(C3="November",11,12)))))))))))),"",TEXT(B9,"DDDD")) | D9: 0 | E9: =IF(AND(MONTH(DATE(VALUE(D3),IF(C3="January",1,IF(C3="February",2,IF(C3="March",3,IF(C3="April",4,IF(C3="May",5,IF(C3="June",6,IF(C3="July",7,IF(C3="August",8,IF(C3="September",9,IF(C3="October",10,IF(C3="November",11,12))))))))))),1)-WEEKDAY(DATE(VALUE(D3),IF(C3="January",1,IF(C3="February",2,IF(C3="March",3,IF(C3="April",4,IF(C3="May",5,IF(C3="June",6,IF(C3="July",7,IF(C3="August",8,IF(C3="September",9,IF(C3="October",10,IF(C3="November",11,12))))))))))),1),3)+1)=IF(C3="January",1,IF(C3="February",2,IF(C3="March",3,IF(C3="April",4,IF(C3="May",5,IF(C3="June",6,IF(C3="July",7,IF(C3="August",8,IF(C3="September",9,IF(C3="October",10,IF(C3="November",11,12))))))))))),NOT(TEXT(DATE(VALUE(D3),IF(C3="January",1,IF(C3="February",2,IF(C3="March",3,IF(C3="April",4,IF(C3="May",5,IF(C3="June",6,IF(C3="July",7,IF(C3="August",8,IF(C3="September",9,IF(C3="October",10,IF(C3="November",11,12))))))))))),1)-WEEKDAY(DATE(VALUE(D3),IF(C3="January",1,IF(C3="February",2,IF(C3="March",3,IF(C3="April",4,IF(C3="May",5,IF(C3="June",6,IF(C3="July",7,IF(C3="August",8,IF(C3="September",9,IF(C3="October",10,IF(C3="November",11,12))))))))))),1),3)+1,"DDDD")="Thursday"),NOT(L9="Absent")),IF(D9=0,0,D9*0.8),0) -> 0 | F9: =IF(AND(MONTH(DATE(VALUE(D3),IF(C3="January",1,IF(C3="February",2,IF(C3="March",3,IF(C3="April",4,IF(C3="May",5,IF(C3="June",6,IF(C3="July",7,IF(C3="August",8,IF(C3="September",9,IF(C3="October",10,IF(C3="November",11,12))))))))))),1)-WEEKDAY(DATE(VALUE(D3),IF(C3="January",1,IF(C3="February",2,IF(C3="March",3,IF(C3="April",4,IF(C3="May",5,IF(C3="June",6,IF(C3="July",7,IF(C3="August",8,IF(C3="September",9,IF(C3="October",10,IF(C3="November",11,12))))))))))),1),3)+1)=IF(C3="January",1,IF(C3="February",2,IF(C3="March",3,IF(C3="April",4,IF(C3="May",5,IF(C3="June",6,IF(C3="July",7,IF(C3="August",8,IF(C3="September",9,IF(C3="October",10,IF(C3="November",11,12))))))))))),NOT(TEXT(DATE(VALUE(D3),IF(C3="January",1,IF(C3="February",2,IF(C3="March",3,IF(C3="April",4,IF(C3="May",5,IF(C3="June",6,IF(C3="July",7,IF(C3="August",8,IF(C3="September",9,IF(C3="October",10,IF(C3="November",11,12))))))))))),1)-WEEKDAY(DATE(VALUE(D3),IF(C3="January",1,IF(C3="February",2,IF(C3="March",3,IF(C3="April",4,IF(C3="May",5,IF(C3="June",6,IF(C3="July",7,IF(C3="August",8,IF(C3="September",9,IF(C3="October",10,IF(C3="November",11,12))))))))))),1),3)+1,"DDDD")="Thursday"),NOT(L9="Absent")),8,0) -> 0 | G9: =IF(AND(MONTH(DATE(VALUE(D3),IF(C3="January",1,IF(C3="February",2,IF(C3="March",3,IF(C3="April",4,IF(C3="May",5,IF(C3="June",6,IF(C3="July",7,IF(C3="August",8,IF(C3="September",9,IF(C3="October",10,IF(C3="November",11,12))))))))))),1)-WEEKDAY(DATE(VALUE(D3),IF(C3="January",1,IF(C3="February",2,IF(C3="March",3,IF(C3="April",4,IF(C3="May",5,IF(C3="June",6,IF(C3="July",7,IF(C3="August",8,IF(C3="September",9,IF(C3="October",10,IF(C3="November",11,12))))))))))),1),3)+1)=IF(C3="January",1,IF(C3="February",2,IF(C3="March",3,IF(C3="April",4,IF(C3="May",5,IF(C3="June",6,IF(C3="July",7,IF(C3="August",8,IF(C3="September",9,IF(C3="October",10,IF(C3="November",11,12))))))))))),NOT(TEXT(DATE(VALUE(D3),IF(C3="January",1,IF(C3="February",2,IF(C3="March",3,IF(C3="April",4,IF(C3="May",5,IF(C3="June",6,IF(C3="July",7,IF(C3="August",8,IF(C3="September",9,IF(C3="October",10,IF(C3="November",11,12))))))))))),1)-WEEKDAY(DATE(VALUE(D3),IF(C3="January",1,IF(C3="February",2,IF(C3="March",3,IF(C3="April",4,IF(C3="May",5,IF(C3="June",6,IF(C3="July",7,IF(C3="August",8,IF(C3="September",9,IF(C3="October",10,IF(C3="November",11,12))))))))))),1),3)+1,"DDDD")="Thursday"),NOT(L9="Absent")),F9*2,0) -> 0 | H9: =IF(NOT(MONTH(DATE(VALUE(D3),IF(C3="January",1,IF(C3="February",2,IF(C3="March",3,IF(C3="April",4,IF(C3="May",5,IF(C3="June",6,IF(C3="July",7,IF(C3="August",8,IF(C3="September",9,IF(C3="October",10,IF(C3="November",11,12))))))))))),1)-WEEKDAY(DATE(VALUE(D3),IF(C3="January",1,IF(C3="February",2,IF(C3="March",3,IF(C3="April",4,IF(C3="May",5,IF(C3="June",6,IF(C3="July",7,IF(C3="August",8,IF(C3="September",9,IF(C3="October",10,IF(C3="November",11,12))))))))))),1),3)+1)=IF(C3="January",1,IF(C3="February",2,IF(C3="March",3,IF(C3="April",4,IF(C3="May",5,IF(C3="June",6,IF(C3="July",7,IF(C3="August",8,IF(C3="September",9,IF(C3="October",10,IF(C3="November",11,12)))))))))))),"",IF(TEXT(DATE(VALUE(D3),IF(C3="January",1,IF(C3="February",2,IF(C3="March",3,IF(C3="April",4,IF(C3="May",5,IF(C3="June",6,IF(C3="July",7,IF(C3="August",8,IF(C3="September",9,IF(C3="October",10,IF(C3="November",11,12))))))))))),1)-WEEKDAY(DATE(VALUE(D3),IF(C3="January",1,IF(C3="February",2,IF(C3="March",3,IF(C3="April",4,IF(C3="May",5,IF(C3="June",6,IF(C3="July",7,IF(C3="August",8,IF(C3="September",9,IF(C3="October",10,IF(C3="November",11,12))))))))))),1),3)+1,"DDDD")="Thursday","—",IF(L9="Absent","Absent",IF(E9=0,"0%",IF(E9<500,"3%",IF(E9<1000,"4%","5%")))))) | I9: =IF(AND(MONTH(DATE(VALUE(D3),IF(C3="January",1,IF(C3="February",2,IF(C3="March",3,IF(C3="April",4,IF(C3="May",5,IF(C3="June",6,IF(C3="July",7,IF(C3="August",8,IF(C3="September",9,IF(C3="October",10,IF(C3="November",11,12))))))))))),1)-WEEKDAY(DATE(VALUE(D3),IF(C3="January",1,IF(C3="February",2,IF(C3="March",3,IF(C3="April",4,IF(C3="May",5,IF(C3="June",6,IF(C3="July",7,IF(C3="August",8,IF(C3="September",9,IF(C3="October",10,IF(C3="November",11,12))))))))))),1),3)+1)=IF(C3="January",1,IF(C3="February",2,IF(C3="March",3,IF(C3="April",4,IF(C3="May",5,IF(C3="June",6,IF(C3="July",7,IF(C3="August",8,IF(C3="September",9,IF(C3="October",10,IF(C3="November",11,12))))))))))),NOT(TEXT(DATE(VALUE(D3),IF(C3="January",1,IF(C3="February",2,IF(C3="March",3,IF(C3="April",4,IF(C3="May",5,IF(C3="June",6,IF(C3="July",7,IF(C3="August",8,IF(C3="September",9,IF(C3="October",10,IF(C3="November",11,12))))))))))),1)-WEEKDAY(DATE(VALUE(D3),IF(C3="January",1,IF(C3="February",2,IF(C3="March",3,IF(C3="April",4,IF(C3="May",5,IF(C3="June",6,IF(C3="July",7,IF(C3="August",8,IF(C3="September",9,IF(C3="October",10,IF(C3="November",11,12))))))))))),1),3)+1,"DDDD")="Thursday"),NOT(L9="Absent")),IF(E9=0,0,IF(E9<500,E9*0.03,IF(E9<1000,E9*0.04,E9*0.05))),0) -> 0 | J9: =IF(AND(MONTH(DATE(VALUE(D3),IF(C3="January",1,IF(C3="February",2,IF(C3="March",3,IF(C3="April",4,IF(C3="May",5,IF(C3="June",6,IF(C3="July",7,IF(C3="August",8,IF(C3="September",9,IF(C3="October",10,IF(C3="November",11,12))))))))))),1)-WEEKDAY(DATE(VALUE(D3),IF(C3="January",1,IF(C3="February",2,IF(C3="March",3,IF(C3="April",4,IF(C3="May",5,IF(C3="June",6,IF(C3="July",7,IF(C3="August",8,IF(C3="September",9,IF(C3="October",10,IF(C3="November",11,12))))))))))),1),3)+1)=IF(C3="January",1,IF(C3="February",2,IF(C3="March",3,IF(C3="April",4,IF(C3="May",5,IF(C3="June",6,IF(C3="July",7,IF(C3="August",8,IF(C3="September",9,IF(C3="October",10,IF(C3="November",11,12))))))))))),NOT(TEXT(DATE(VALUE(D3),IF(C3="January",1,IF(C3="February",2,IF(C3="March",3,IF(C3="April",4,IF(C3="May",5,IF(C3="June",6,IF(C3="July",7,IF(C3="August",8,IF(C3="September",9,IF(C3="October",10,IF(C3="November",11,12))))))))))),1)-WEEKDAY(DATE(VALUE(D3),IF(C3="January",1,IF(C3="February",2,IF(C3="March",3,IF(C3="April",4,IF(C3="May",5,IF(C3="June",6,IF(C3="July",7,IF(C3="August",8,IF(C3="September",9,IF(C3="October",10,IF(C3="November",11,12))))))))))),1),3)+1,"DDDD")="Thursday"),NOT(L9="Absent")),G9+I9,0) -> 0 | K9: =IF(AND(MONTH(DATE(VALUE(D3),IF(C3="January",1,IF(C3="February",2,IF(C3="March",3,IF(C3="April",4,IF(C3="May",5,IF(C3="June",6,IF(C3="July",7,IF(C3="August",8,IF(C3="September",9,IF(C3="October",10,IF(C3="November",11,12))))))))))),1)-WEEKDAY(DATE(VALUE(D3),IF(C3="January",1,IF(C3="February",2,IF(C3="March",3,IF(C3="April",4,IF(C3="May",5,IF(C3="June",6,IF(C3="July",7,IF(C3="August",8,IF(C3="September",9,IF(C3="October",10,IF(C3="November",11,12))))))))))),1),3)+1)=IF(C3="January",1,IF(C3="February",2,IF(C3="March",3,IF(C3="April",4,IF(C3="May",5,IF(C3="June",6,IF(C3="July",7,IF(C3="August",8,IF(C3="September",9,IF(C3="October",10,IF(C3="November",11,12))))))))))),NOT(TEXT(DATE(VALUE(D3),IF(C3="January",1,IF(C3="February",2,IF(C3="March",3,IF(C3="April",4,IF(C3="May",5,IF(C3="June",6,IF(C3="July",7,IF(C3="August",8,IF(C3="September",9,IF(C3="October",10,IF(C3="November",11,12))))))))))),1)-WEEKDAY(DATE(VALUE(D3),IF(C3="January",1,IF(C3="February",2,IF(C3="March",3,IF(C3="April",4,IF(C3="May",5,IF(C3="June",6,IF(C3="July",7,IF(C3="August",8,IF(C3="September",9,IF(C3="October",10,IF(C3="November",11,12))))))))))),1),3)+1,"DDDD")="Thursday"),NOT(L9="Absent")),J9*$L$3,0) -> 0
A10: =IF(NOT(MONTH(DATE(VALUE(D3),IF(C3="January",1,IF(C3="February",2,IF(C3="March",3,IF(C3="April",4,IF(C3="May",5,IF(C3="June",6,IF(C3="July",7,IF(C3="August",8,IF(C3="September",9,IF(C3="October",10,IF(C3="November",11,12))))))))))),1)-WEEKDAY(DATE(VALUE(D3),IF(C3="January",1,IF(C3="February",2,IF(C3="March",3,IF(C3="April",4,IF(C3="May",5,IF(C3="June",6,IF(C3="July",7,IF(C3="August",8,IF(C3="September",9,IF(C3="October",10,IF(C3="November",11,12))))))))))),1),3)+2)=IF(C3="January",1,IF(C3="February",2,IF(C3="March",3,IF(C3="April",4,IF(C3="May",5,IF(C3="June",6,IF(C3="July",7,IF(C3="August",8,IF(C3="September",9,IF(C3="October",10,IF(C3="November",11,12)))))))))))),"",IF(TEXT(DATE(VALUE(D3),IF(C3="January",1,IF(C3="February",2,IF(C3="March",3,IF(C3="April",4,IF(C3="May",5,IF(C3="June",6,IF(C3="July",7,IF(C3="August",8,IF(C3="September",9,IF(C3="October",10,IF(C3="November",11,12))))))))))),1)-WEEKDAY(DATE(VALUE(D3),IF(C3="January",1,IF(C3="February",2,IF(C3="March",3,IF(C3="April",4,IF(C3="May",5,IF(C3="June",6,IF(C3="July",7,IF(C3="August",8,IF(C3="September",9,IF(C3="October",10,IF(C3="November",11,12))))))))))),1),3)+2,"DDDD")="Thursday","—",DAY(DATE(VALUE(D3),IF(C3="January",1,IF(C3="February",2,IF(C3="March",3,IF(C3="April",4,IF(C3="May",5,IF(C3="June",6,IF(C3="July",7,IF(C3="August",8,IF(C3="September",9,IF(C3="October",10,IF(C3="November",11,12))))))))))),1)-WEEKDAY(DATE(VALUE(D3),IF(C3="January",1,IF(C3="February",2,IF(C3="March",3,IF(C3="April",4,IF(C3="May",5,IF(C3="June",6,IF(C3="July",7,IF(C3="August",8,IF(C3="September",9,IF(C3="October",10,IF(C3="November",11,12))))))))))),1),3)+2))) | B10: =IF(NOT(MONTH(DATE(VALUE(D3),IF(C3="January",1,IF(C3="February",2,IF(C3="March",3,IF(C3="April",4,IF(C3="May",5,IF(C3="June",6,IF(C3="July",7,IF(C3="August",8,IF(C3="September",9,IF(C3="October",10,IF(C3="November",11,12))))))))))),1)-WEEKDAY(DATE(VALUE(D3),IF(C3="January",1,IF(C3="February",2,IF(C3="March",3,IF(C3="April",4,IF(C3="May",5,IF(C3="June",6,IF(C3="July",7,IF(C3="August",8,IF(C3="September",9,IF(C3="October",10,IF(C3="November",11,12))))))))))),1),3)+2)=IF(C3="January",1,IF(C3="February",2,IF(C3="March",3,IF(C3="April",4,IF(C3="May",5,IF(C3="June",6,IF(C3="July",7,IF(C3="August",8,IF(C3="September",9,IF(C3="October",10,IF(C3="November",11,12)))))))))))),"",DATE(VALUE(D3),IF(C3="January",1,IF(C3="February",2,IF(C3="March",3,IF(C3="April",4,IF(C3="May",5,IF(C3="June",6,IF(C3="July",7,IF(C3="August",8,IF(C3="September",9,IF(C3="October",10,IF(C3="November",11,12))))))))))),1)-WEEKDAY(DATE(VALUE(D3),IF(C3="January",1,IF(C3="February",2,IF(C3="March",3,IF(C3="April",4,IF(C3="May",5,IF(C3="June",6,IF(C3="July",7,IF(C3="August",8,IF(C3="September",9,IF(C3="October",10,IF(C3="November",11,12))))))))))),1),3)+2) | C10: =IF(NOT(MONTH(DATE(VALUE(D3),IF(C3="January",1,IF(C3="February",2,IF(C3="March",3,IF(C3="April",4,IF(C3="May",5,IF(C3="June",6,IF(C3="July",7,IF(C3="August",8,IF(C3="September",9,IF(C3="October",10,IF(C3="November",11,12))))))))))),1)-WEEKDAY(DATE(VALUE(D3),IF(C3="January",1,IF(C3="February",2,IF(C3="March",3,IF(C3="April",4,IF(C3="May",5,IF(C3="June",6,IF(C3="July",7,IF(C3="August",8,IF(C3="September",9,IF(C3="October",10,IF(C3="November",11,12))))))))))),1),3)+2)=IF(C3="January",1,IF(C3="February",2,IF(C3="March",3,IF(C3="April",4,IF(C3="May",5,IF(C3="June",6,IF(C3="July",7,IF(C3="August",8,IF(C3="September",9,IF(C3="October",10,IF(C3="November",11,12)))))))))))),"",TEXT(B10,"DDDD")) | D10: 0 | E10: =IF(AND(MONTH(DATE(VALUE(D3),IF(C3="January",1,IF(C3="February",2,IF(C3="March",3,IF(C3="April",4,IF(C3="May",5,IF(C3="June",6,IF(C3="July",7,IF(C3="August",8,IF(C3="September",9,IF(C3="October",10,IF(C3="November",11,12))))))))))),1)-WEEKDAY(DATE(VALUE(D3),IF(C3="January",1,IF(C3="February",2,IF(C3="March",3,IF(C3="April",4,IF(C3="May",5,IF(C3="June",6,IF(C3="July",7,IF(C3="August",8,IF(C3="September",9,IF(C3="October",10,IF(C3="November",11,12))))))))))),1),3)+2)=IF(C3="January",1,IF(C3="February",2,IF(C3="March",3,IF(C3="April",4,IF(C3="May",5,IF(C3="June",6,IF(C3="July",7,IF(C3="August",8,IF(C3="September",9,IF(C3="October",10,IF(C3="November",11,12))))))))))),NOT(TEXT(DATE(VALUE(D3),IF(C3="January",1,IF(C3="February",2,IF(C3="March",3,IF(C3="April",4,IF(C3="May",5,IF(C3="June",6,IF(C3="July",7,IF(C3="August",8,IF(C3="September",9,IF(C3="October",10,IF(C3="November",11,12))))))))))),1)-WEEKDAY(DATE(VALUE(D3),IF(C3="January",1,IF(C3="February",2,IF(C3="March",3,IF(C3="April",4,IF(C3="May",5,IF(C3="June",6,IF(C3="July",7,IF(C3="August",8,IF(C3="September",9,IF(C3="October",10,IF(C3="November",11,12))))))))))),1),3)+2,"DDDD")="Thursday"),NOT(L10="Absent")),IF(D10=0,0,D10*0.8),0) -> 0 | F10: =IF(AND(MONTH(DATE(VALUE(D3),IF(C3="January",1,IF(C3="February",2,IF(C3="March",3,IF(C3="April",4,IF(C3="May",5,IF(C3="June",6,IF(C3="July",7,IF(C3="August",8,IF(C3="September",9,IF(C3="October",10,IF(C3="November",11,12))))))))))),1)-WEEKDAY(DATE(VALUE(D3),IF(C3="January",1,IF(C3="February",2,IF(C3="March",3,IF(C3="April",4,IF(C3="May",5,IF(C3="June",6,IF(C3="July",7,IF(C3="August",8,IF(C3="September",9,IF(C3="October",10,IF(C3="November",11,12))))))))))),1),3)+2)=IF(C3="January",1,IF(C3="February",2,IF(C3="March",3,IF(C3="April",4,IF(C3="May",5,IF(C3="June",6,IF(C3="July",7,IF(C3="August",8,IF(C3="September",9,IF(C3="October",10,IF(C3="November",11,12))))))))))),NOT(TEXT(DATE(VALUE(D3),IF(C3="January",1,IF(C3="February",2,IF(C3="March",3,IF(C3="April",4,IF(C3="May",5,IF(C3="June",6,IF(C3="July",7,IF(C3="August",8,IF(C3="September",9,IF(C3="October",10,IF(C3="November",11,12))))))))))),1)-WEEKDAY(DATE(VALUE(D3),IF(C3="January",1,IF(C3="February",2,IF(C3="March",3,IF(C3="April",4,IF(C3="May",5,IF(C3="June",6,IF(C3="July",7,IF(C3="August",8,IF(C3="September",9,IF(C3="October",10,IF(C3="November",11,12))))))))))),1),3)+2,"DDDD")="Thursday"),NOT(L10="Absent")),8,0) -> 0 | G10: =IF(AND(MONTH(DATE(VALUE(D3),IF(C3="January",1,IF(C3="February",2,IF(C3="March",3,IF(C3="April",4,IF(C3="May",5,IF(C3="June",6,IF(C3="July",7,IF(C3="August",8,IF(C3="September",9,IF(C3="October",10,IF(C3="November",11,12))))))))))),1)-WEEKDAY(DATE(VALUE(D3),IF(C3="January",1,IF(C3="February",2,IF(C3="March",3,IF(C3="April",4,IF(C3="May",5,IF(C3="June",6,IF(C3="July",7,IF(C3="August",8,IF(C3="September",9,IF(C3="October",10,IF(C3="November",11,12))))))))))),1),3)+2)=IF(C3="January",1,IF(C3="February",2,IF(C3="March",3,IF(C3="April",4,IF(C3="May",5,IF(C3="June",6,IF(C3="July",7,IF(C3="August",8,IF(C3="September",9,IF(C3="October",10,IF(C3="November",11,12))))))))))),NOT(TEXT(DATE(VALUE(D3),IF(C3="January",1,IF(C3="February",2,IF(C3="March",3,IF(C3="April",4,IF(C3="May",5,IF(C3="June",6,IF(C3="July",7,IF(C3="August",8,IF(C3="September",9,IF(C3="October",10,IF(C3="November",11,12))))))))))),1)-WEEKDAY(DATE(VALUE(D3),IF(C3="January",1,IF(C3="February",2,IF(C3="March",3,IF(C3="April",4,IF(C3="May",5,IF(C3="June",6,IF(C3="July",7,IF(C3="August",8,IF(C3="September",9,IF(C3="October",10,IF(C3="November",11,12))))))))))),1),3)+2,"DDDD")="Thursday"),NOT(L10="Absent")),F10*2,0) -> 0 | H10: =IF(NOT(MONTH(DATE(VALUE(D3),IF(C3="January",1,IF(C3="February",2,IF(C3="March",3,IF(C3="April",4,IF(C3="May",5,IF(C3="June",6,IF(C3="July",7,IF(C3="August",8,IF(C3="September",9,IF(C3="October",10,IF(C3="November",11,12))))))))))),1)-WEEKDAY(DATE(VALUE(D3),IF(C3="January",1,IF(C3="February",2,IF(C3="March",3,IF(C3="April",4,IF(C3="May",5,IF(C3="June",6,IF(C3="July",7,IF(C3="August",8,IF(C3="September",9,IF(C3="October",10,IF(C3="November",11,12))))))))))),1),3)+2)=IF(C3="January",1,IF(C3="February",2,IF(C3="March",3,IF(C3="April",4,IF(C3="May",5,IF(C3="June",6,IF(C3="July",7,IF(C3="August",8,IF(C3="September",9,IF(C3="October",10,IF(C3="November",11,12)))))))))))),"",IF(TEXT(DATE(VALUE(D3),IF(C3="January",1,IF(C3="February",2,IF(C3="March",3,IF(C3="April",4,IF(C3="May",5,IF(C3="June",6,IF(C3="July",7,IF(C3="August",8,IF(C3="September",9,IF(C3="October",10,IF(C3="November",11,12))))))))))),1)-WEEKDAY(DATE(VALUE(D3),IF(C3="January",1,IF(C3="February",2,IF(C3="March",3,IF(C3="April",4,IF(C3="May",5,IF(C3="June",6,IF(C3="July",7,IF(C3="August",8,IF(C3="September",9,IF(C3="October",10,IF(C3="November",11,12))))))))))),1),3)+2,"DDDD")="Thursday","—",IF(L10="Absent","Absent",IF(E10=0,"0%",IF(E10<500,"3%",IF(E10<1000,"4%","5%")))))) | I10: =IF(AND(MONTH(DATE(VALUE(D3),IF(C3="January",1,IF(C3="February",2,IF(C3="March",3,IF(C3="April",4,IF(C3="May",5,IF(C3="June",6,IF(C3="July",7,IF(C3="August",8,IF(C3="September",9,IF(C3="October",10,IF(C3="November",11,12))))))))))),1)-WEEKDAY(DATE(VALUE(D3),IF(C3="January",1,IF(C3="February",2,IF(C3="March",3,IF(C3="April",4,IF(C3="May",5,IF(C3="June",6,IF(C3="July",7,IF(C3="August",8,IF(C3="September",9,IF(C3="October",10,IF(C3="November",11,12))))))))))),1),3)+2)=IF(C3="January",1,IF(C3="February",2,IF(C3="March",3,IF(C3="April",4,IF(C3="May",5,IF(C3="June",6,IF(C3="July",7,IF(C3="August",8,IF(C3="September",9,IF(C3="October",10,IF(C3="November",11,12))))))))))),NOT(TEXT(DATE(VALUE(D3),IF(C3="January",1,IF(C3="February",2,IF(C3="March",3,IF(C3="April",4,IF(C3="May",5,IF(C3="June",6,IF(C3="July",7,IF(C3="August",8,IF(C3="September",9,IF(C3="October",10,IF(C3="November",11,12))))))))))),1)-WEEKDAY(DATE(VALUE(D3),IF(C3="January",1,IF(C3="February",2,IF(C3="March",3,IF(C3="April",4,IF(C3="May",5,IF(C3="June",6,IF(C3="July",7,IF(C3="August",8,IF(C3="September",9,IF(C3="October",10,IF(C3="November",11,12))))))))))),1),3)+2,"DDDD")="Thursday"),NOT(L10="Absent")),IF(E10=0,0,IF(E10<500,E10*0.03,IF(E10<1000,E10*0.04,E10*0.05))),0) -> 0 | J10: =IF(AND(MONTH(DATE(VALUE(D3),IF(C3="January",1,IF(C3="February",2,IF(C3="March",3,IF(C3="April",4,IF(C3="May",5,IF(C3="June",6,IF(C3="July",7,IF(C3="August",8,IF(C3="September",9,IF(C3="October",10,IF(C3="November",11,12))))))))))),1)-WEEKDAY(DATE(VALUE(D3),IF(C3="January",1,IF(C3="February",2,IF(C3="March",3,IF(C3="April",4,IF(C3="May",5,IF(C3="June",6,IF(C3="July",7,IF(C3="August",8,IF(C3="September",9,IF(C3="October",10,IF(C3="November",11,12))))))))))),1),3)+2)=IF(C3="January",1,IF(C3="February",2,IF(C3="March",3,IF(C3="April",4,IF(C3="May",5,IF(C3="June",6,IF(C3="July",7,IF(C3="August",8,IF(C3="September",9,IF(C3="October",10,IF(C3="November",11,12))))))))))),NOT(TEXT(DATE(VALUE(D3),IF(C3="January",1,IF(C3="February",2,IF(C3="March",3,IF(C3="April",4,IF(C3="May",5,IF(C3="June",6,IF(C3="July",7,IF(C3="August",8,IF(C3="September",9,IF(C3="October",10,IF(C3="November",11,12))))))))))),1)-WEEKDAY(DATE(VALUE(D3),IF(C3="January",1,IF(C3="February",2,IF(C3="March",3,IF(C3="April",4,IF(C3="May",5,IF(C3="June",6,IF(C3="July",7,IF(C3="August",8,IF(C3="September",9,IF(C3="October",10,IF(C3="November",11,12))))))))))),1),3)+2,"DDDD")="Thursday"),NOT(L10="Absent")),G10+I10,0) -> 0 | K10: =IF(AND(MONTH(DATE(VALUE(D3),IF(C3="January",1,IF(C3="February",2,IF(C3="March",3,IF(C3="April",4,IF(C3="May",5,IF(C3="June",6,IF(C3="July",7,IF(C3="August",8,IF(C3="September",9,IF(C3="October",10,IF(C3="November",11,12))))))))))),1)-WEEKDAY(DATE(VALUE(D3),IF(C3="January",1,IF(C3="February",2,IF(C3="March",3,IF(C3="April",4,IF(C3="May",5,IF(C3="June",6,IF(C3="July",7,IF(C3="August",8,IF(C3="September",9,IF(C3="October",10,IF(C3="November",11,12))))))))))),1),3)+2)=IF(C3="January",1,IF(C3="February",2,IF(C3="March",3,IF(C3="April",4,IF(C3="May",5,IF(C3="June",6,IF(C3="July",7,IF(C3="August",8,IF(C3="September",9,IF(C3="October",10,IF(C3="November",11,12))))))))))),NOT(TEXT(DATE(VALUE(D3),IF(C3="January",1,IF(C3="February",2,IF(C3="March",3,IF(C3="April",4,IF(C3="May",5,IF(C3="June",6,IF(C3="July",7,IF(C3="August",8,IF(C3="September",9,IF(C3="October",10,IF(C3="November",11,12))))))))))),1)-WEEKDAY(DATE(VALUE(D3),IF(C3="January",1,IF(C3="February",2,IF(C3="March",3,IF(C3="April",4,IF(C3="May",5,IF(C3="June",6,IF(C3="July",7,IF(C3="August",8,IF(C3="September",9,IF(C3="October",10,IF(C3="November",11,12))))))))))),1),3)+2,"DDDD")="Thursday"),NOT(L10="Absent")),J10*$L$3,0) -> 0
